Workbook
Name SegmentaciónDeDatos_Docente: #N/A

Sheet Sobre la Encuesta
B12: ¿Quiénes respondieron la encuesta? | D12: ¿Qué encontrará en este archivo?
B13: Todos/as los/as estudiantes que se inscribieron en alguna materia durante el cuatrimestre anterior (aunque no la hayan cursado finalmente). | D13: ▪️Una síntesis de resultados ▪️La base de datos con las respuestas de los/as estudiantes
B14: ¿Cuándo la respondieron? | D14: ¿Cómo se elabora la síntesis de resultados?
B15: Al inscribirse a las materias del cuatrimestre en curso. El sistema SIU Guaraní solicitó completar la encuesta como condición para finalizar la inscripción. | D15: Con las respuestas brindadas por los/as estudiantes se realizan tres cálculos: ▪️Valoración por pregunta: es el promedio de todas las respuestas que recibió cada pregunta. ▪️Valoración por dimensión: es el promedio de todas las respuestas que obtuvieron las preguntas de cada dimensión. ▪️Valoración global: es el promedio de las 6 dimensiones evaluadas.
B16: ¿Qué aspectos evalúa? | D16: ¿Qué encontrará en la hoja "síntesis de resultados"?
B17: La encuesta aborda seis dimensiones relacionadas con el/la docente principal de la comisión*: 1- La planificación y la organización de la materia. 2- Los contenidos. 3- Las clases y las actividades. 4- La evaluación. 5- El ambiente de aprendizaje y el vínculo interpersonal. 6- Balance general. Además, a quienes abandonaron la materia se les consulta el motivo de abandono. *Cada estudiante indica, en una pregunta abierta, sobre qué docente responde la encuesta. Por lo tanto, dentro de una misma comisión, esta información puede variar según la percepción de cada estudiante. Cada pregunta de las dimensiones admite una respuesta de 1 a 5 según el grado de acuerdo: 1- Nada de acuerdo 2- Poco de acuerdo 3- Medianamente de acuerdo 4- De acuerdo 5- Muy de acuerdo | D17: Información que permitirá identificar fortalezas y aspectos que pueden mejorarse ▪️La valoración global de la comisión. ▪️La valoración promedio de cada dimensión. ▪️El detalle de la valoración por cada pregunta. Para facilitar la lectura se utiliza un sistema de colores: GRIS: 1 a 3,4 GRIS OSCURO: 3,5 a 3,9 CELESTE: 4 a 4,4 AZUL: 4,5 a 5

Sheet Síntesis de Resultados
B20: DOCENTES (SIU Guaraní): | C20: ROSATI GERMAN FEDERICO (6114)
B21: MATERIA: | C21: (MA-GN00209) - Laboratorio de Datos: webscraping y procesamiento de lenguaje natural
B22: COMISIÓN: | C22: (82009) - Laboratorio de Datos tn Rosati
B23: CANTIDAD DE INSCRIPTOS/AS: | C23: 11 | J23: VALORACIÓN GLOBAL | K23: =IFERROR(AVERAGE(E27,E35,H27,H35,K27,K35),"-") -> -
B24: ENCUESTAS RESPONDIDAS: | C24: 9
B25: TASA DE RESPUESTA: | C25: 82%
B27: DOCENTE (sobre el/la que responde el estudiante)*: | D27: LA PLANIFICACIÓN Y LA ORGANIZACIÓN DE LA MATERIA | E27: =IFERROR(AVERAGE(E29:E32),"-") -> - | G27: LOS CONTENIDOS DE LA MATERIA | H27: =IFERROR(AVERAGE(H29:H31),"-") -> - | J27: LAS CLASES Y LAS ACTIVIDADES | K27: =IFERROR(AVERAGE(K29:K32),"-") -> -
D29: Al inicio de la cursada el/la docente presentó y explicó claramente el programa de la materia. (detalló objetivos, contenidos, cronograma, formas de trabajo y evaluación). | E29: =IFERROR(AVERAGE(_DinamicaProm!B6:B400),"-") -> - | G29: El/la docente relacionó conceptos con otros aprendidos con anterioridad en la misma materia o en otras materias. | H29: =IFERROR(AVERAGE(_DinamicaProm!F6:F400),"-") -> - | J29: El/la docente desarrolló los temas con claridad. | K29: =IFERROR(AVERAGE(_DinamicaProm!I6:I400),"-") -> -
D30: Hubo coherencia entre lo programado y el desarrollo de la materia | E30: =IFERROR(AVERAGE(_DinamicaProm!C6:C400),"-") -> - | G30: El/la docente usó ejemplos y casos relacionados con la realidad y/o el mundo laboral. | H30: =IFERROR(AVERAGE(_DinamicaProm!G6:G400),"-") -> - | J30: El/la docente fomentó la participación en clase | K30: =IFERROR(AVERAGE(_DinamicaProm!J6:J400),"-") -> -
D31: Todos los contenidos tuvieron el tiempo suficiente para lograr los aprendizajes esperados | E31: =IFERROR(AVERAGE(_DinamicaProm!D6:D400),"-") -> - | G31: Los recursos y/o bibliografía propuestos me sirvieron para comprender las temáticas de la asignatura. | H31: =IFERROR(AVERAGE(_DinamicaProm!H6:H400),"-") -> - | J31: Las tecnologías digitales que usó el docente me facilitaron el aprendizaje. (Ejemplo: videos, recursos web, programas, presentaciones, etc.). | K31: =IFERROR(AVERAGE(_DinamicaProm!K6:K400),"-") -> -
D32: El/la docente utilizó el Campus Virtual como herramienta de apoyo de la asignatura | E32: =IFERROR(AVERAGE(_DinamicaProm!E6:E400),"-") -> - | J32: Las actividades propuestas en la clase contribuyeron al aprendizaje (trabajos prácticos individuales o grupales, visitas, etc.) | K32: =IFERROR(AVERAGE(_DinamicaProm!L6:L400),"-") -> -
B34: *Cada estudiante indica en la encuesta el nombre del docente sobre el que responde. Por ende, dentro de una misma comisión pueden aparecer respuestas sobre más de un docente, y su nombre puede estar escrito de diversas formas. Seleccione todas las veces que figure en la lista el nombre del docente sobre el cual quiere ver los resultados.
D35: LA EVALUACIÓN | E35: =IFERROR(AVERAGE(E37:E41),"-") -> - | G35: EL AMBIENTE DE APRENDIZAJE Y EL VÍNCULO INTERPERSONAL | H35: =IFERROR(AVERAGE(H37:H40),"-") -> - | J35: BALANCE | K35: =IFERROR(AVERAGE(K37:K38),"-") -> -
D37: El/la docente comunicó claramente los criterios de evaluación antes de cada evaluación. | E37: =IFERROR(AVERAGE(_DinamicaProm!M6:M400),"-") -> - | G37: El/la docente estableció un ambiente agradable/seguro/de confianza para el aprendizaje. | H37: =IFERROR(AVERAGE(_DinamicaProm!R6:R400),"-") -> - | J37: He aprendido y comprendido los contenidos de esta materia. | K37: =IFERROR(AVERAGE(_DinamicaProm!V6:V400),"-") -> -
D38: La evaluación se correspondió con lo enseñado. | E38: =IFERROR(AVERAGE(_DinamicaProm!N6:N400),"-") -> - | G38: El/la docente promovió un trato respetuoso entre todas las personas, independientemente de su origen social, género u orientación sexual o política. | H38: =IFERROR(AVERAGE(_DinamicaProm!S6:S400),"-") -> - | J38: La materia contribuyó a confirmar mi elección por la carrera. | K38: =IFERROR(AVERAGE(_DinamicaProm!W6:W400),"-") -> -
D39: Los instrumentos para evaluar fueron adecuados (multiple choice, examen oral, examen escrito, etc). | E39: =IFERROR(AVERAGE(_DinamicaProm!O6:O400),"-") -> - | G39: El/la docente acogió positivamente las preguntas e inquietudes de los/as estudiantes. | H39: =IFERROR(AVERAGE(_DinamicaProm!T6:T400),"-") -> -
D40: Después de las evaluaciones, el/la docente realizó una devolución de los resultados a los/as estudiantes para mejorar los aprendizajes. | E40: =IFERROR(AVERAGE(_DinamicaProm!P6:P400),"-") -> - | G40: El/la docente generó interés en la materia y ganas de aprender. | H40: =IFERROR(AVERAGE(_DinamicaProm!U6:U400),"-") -> -
D41: El/la docente realizó las devoluciones en un tiempo adecuado. | E41: =IFERROR(AVERAGE(_DinamicaProm!Q6:Q400),"-") -> -

Sheet Base Encuesta
A18: Fuente: SIU Kolla - Dirección General de Información y Transparencia Institucional - Secretaría General
L19: MOTIVOS DE ABANDONO | P19: DOCENTE SOBRE EL QUE SE RESPONDE | R19: LA PLANIFICACIÓN Y LA ORGANIZACIÓN DE LA MATERIA | W19: LOS CONTENIDOS DE LA MATERIA | Z19: LAS CLASES Y LAS ACTIVIDADES | AE19: LA EVALUACIÓN | AL19: EL AMBIENTE DE APRENDIZAJE Y EL VÍNCULO INTERPERSONAL | AQ19: BALANCE
A20: Año Académico | B20: Período Lectivo | C20: ID Encuesta | D20: Unidad Académica Nombre | E20: Materia Código | F20: Materia Nombre | G20: Comisión Código | H20: Comisión Nombre | I20: Docentes (SIU Guaraní) | J20: Carrera que estás cursando: | K20: Tu situación en relación a esta materia | L20: Marcá el motivo principal por el cual abandonaste o no iniciaste la cursada | M20: ¿Cuál problema? Seleccioná sólo una | N20: ¿Cuál? | O20: Indicá el momento en que interrumpiste la cursada: | P20: Apellido y nombre del/de la docente: | Q20: ¿Tus comentarios sobre el/la docente? | R20: 1.1 Al inicio de la cursada el/la docente presentó y explicó claramente el programa de la materia (detalló objetivos, contenidos, cronograma, formas de trabajo y evaluación). | S20: 1.2 Hubo coherencia entre lo programado y el desarrollo de la materia. | T20: 1.3 Todos los contenidos tuvieron el tiempo suficiente para lograr los aprendizajes esperados. | U20: 1.A ¿Cuál de los contenidos hubiera requerido más tiempo? | V20: 1.4 El/la docente utilizó el Campus Virtual como herramienta de apoyo de la asignatura. | W20: 2.1 El/la docente relacionó conceptos con otros aprendidos con anterioridad en la misma materia o en otras materias. | X20: 2.2 El/la docente usó ejemplos y casos relacionados con la realidad y/o el mundo laboral. | Y20: 2.3 Los recursos y/o bibliografía propuestos me sirvieron para comprender las temáticas de la asignatura. | Z20: 3.1 El/la docente desarrolló los temas con claridad. | AA20: 3.2 El/la docente fomentó la participación en clase | AB20: 3.3 Las tecnologías digitales que usó el docente me facilitaron el aprendizaje (Ejemplo: videos, recursos web, programas, presentaciones, etc.). | AC20: 3.4 Las actividades propuestas en la clase contribuyeron al aprendizaje (trabajos prácticos individuales o grupales, visitas, etc.) | AD20: 3.A ¿Qué actividad de las propuestas te aportó más en tu aprendizaje y recomendarías mantener? | AE20: 4 ¿Tuviste instancias de evaluación de los contenidos? | AF20: 4.1 El/la docente comunicó claramente los criterios de evaluación antes de cada evaluación. | AG20: 4.2 La evaluación se correspondió con lo enseñado. | AH20: 4.3 Los instrumentos para evaluar fueron adecuados (multiple choice, examen oral, examen escrito, etc). | AI20: 4.4 Después de las evaluaciones, el/la docente realizó una devolución de los resultados a los/as estudiantes para mejorar los aprendizajes. | AJ20: 4.5 El/la docente realizó las devoluciones en un tiempo adecuado. | AK20: 4.A ¿Querés agregar algún comentario sobre las evaluaciones? | AL20: 5.1 El/la docente estableció un ambiente agradable/seguro/de confianza para el aprendizaje. | AM20: 5.2 El/la docente promovió un trato respetuoso entre todas las personas, independientemente de su origen social, género u orientación sexual o política. | AN20: 5.3 El/la docente acogió positivamente las preguntas e inquietudes de los/as estudiantes. | AO20: 5.4 El/la docente generó interés en la materia y ganas de aprender. | AP20: 5.A ¿Querés agregar algún comentario sobre el ambiente para el aprendizaje y/o el vínculo interpersonal? | AQ20: 6.1 He aprendido y comprendido los contenidos de esta materia. | AR20: 6.2 La materia contribuyó a confirmar mi elección por la carrera. | AS20: 6.A ¿Qué es para vos lo más importante que aprendiste en esta materia? | AT20: 6.B En general, ¿qué aspectos POSITIVOS destacarías de esta materia? | AU20: 6.C Pensando en futuras ediciones de la materia, ¿qué aspectos considerás que se podrían mejorar? ¿Querés dejar alguna sugerencia para el o la docente? | AV20: ¿Tuviste otro/a docente en esta materia? | AW20: Apellido y nombre del/de el/la otro/a docente: | AX20: Tus comentarios sobre el/la otro/a docente:
A21: 2025 | B21: 2do cuatrimestre | C21: 31008 | D21: Escuela Interdisciplinaria de Altos Estudios Sociales | E21: MA-GN00209 | F21: Laboratorio de Datos: webscraping y procesamiento de lenguaje natural | G21: 82009 | H21: Laboratorio de Datos tn Rosati | I21: ROSATI GERMAN FEDERICO (6114) | J21: Licenciatura en Sociología | K21: 1-Finalicé la cursada (hayas aprobado o no) | L21: No corresponde | M21: No corresponde | N21: No corresponde | O21: No corresponde | P21: Rosati Germán | Q21: Sin respuesta | R21: 5-Muy de acuerdo | S21: 5-Muy de acuerdo | T21: 5-Muy de acuerdo | U21: Sin respuesta | V21: 1-Nada de acuerdo | W21: 5-Muy de acuerdo | X21: 5-Muy de acuerdo | Y21: 5-Muy de acuerdo | Z21: 5-Muy de acuerdo | AA21: 5-Muy de acuerdo | AB21: 5-Muy de acuerdo | AC21: 5-Muy de acuerdo | AD21: Sin respuesta | AE21: 1-Sí | AF21: 5-Muy de acuerdo | AG21: 5-Muy de acuerdo | AH21: 5-Muy de acuerdo | AI21: 5-Muy de acuerdo | AJ21: 5-Muy de acuerdo | AK21: Sin respuesta | AL21: 5-Muy de acuerdo | AM21: 5-Muy de acuerdo | AN21: 5-Muy de acuerdo | AO21: 5-Muy de acuerdo | AP21: Sin respuesta | AQ21: 5-Muy de acuerdo | AR21: 5-Muy de acuerdo | AS21: Sin respuesta | AT21: Sin respuesta | AU21: Sin respuesta | AV21: 2-No | AW21: No corresponde | AX21: No corresponde
A22: 2025 | B22: 2do cuatrimestre | C22: 31009 | D22: Escuela Interdisciplinaria de Altos Estudios Sociales | E22: MA-GN00209 | F22: Laboratorio de Datos: webscraping y procesamiento de lenguaje natural | G22: 82009 | H22: Laboratorio de Datos tn Rosati | I22: ROSATI GERMAN FEDERICO (6114) | J22: Licenciatura en Sociología | K22: 1-Finalicé la cursada (hayas aprobado o no) | L22: No corresponde | M22: No corresponde | N22: No corresponde | O22: No corresponde | P22: Rosati, Germán | Q22: Nos aguantó 2 años | R22: 5-Muy de acuerdo | S22: 5-Muy de acuerdo | T22: 5-Muy de acuerdo | U22: Sin respuesta | V22: 5-Muy de acuerdo | W22: 5-Muy de acuerdo | X22: 5-Muy de acuerdo | Y22: 5-Muy de acuerdo | Z22: 5-Muy de acuerdo | AA22: 5-Muy de acuerdo | AB22: 5-Muy de acuerdo | AC22: 5-Muy de acuerdo | AD22: Todas | AE22: 1-Sí | AF22: 5-Muy de acuerdo | AG22: 5-Muy de acuerdo | AH22: 5-Muy de acuerdo | AI22: 5-Muy de acuerdo | AJ22: 5-Muy de acuerdo | AK22: No | AL22: 5-Muy de acuerdo | AM22: 5-Muy de acuerdo | AN22: 5-Muy de acuerdo | AO22: 5-Muy de acuerdo | AP22: La verdad que fue todo muy bueno | AQ22: 5-Muy de acuerdo | AR22: 5-Muy de acuerdo | AS22: Siento que, en términos metodológicos, es una base que solidificó todo lo visto en las otras materias. | AT22: La posibilidad de pensar las ciencias sociales de otra manera, lo que también implica profundizar más en lo antes visto | AU22: Tener adscriptos todos los cuatris. Sé que es casi utópico, súper difícil de lograr, pero cuando Santi fue adscripto fue una ayuda muy sustantiva. | AV22: 2-No | AW22: No corresponde | AX22: No corresponde
A23: 2025 | B23: 2do cuatrimestre | C23: 31010 | D23: Escuela Interdisciplinaria de Altos Estudios Sociales | E23: MA-GN00209 | F23: Laboratorio de Datos: webscraping y procesamiento de lenguaje natural | G23: 82009 | H23: Laboratorio de Datos tn Rosati | I23: ROSATI GERMAN FEDERICO (6114) | J23: Licenciatura en Sociología | K23: 1-Finalicé la cursada (hayas aprobado o no) | L23: No corresponde | M23: No corresponde | N23: No corresponde | O23: No corresponde | P23: german rosati | Q23: muy buen docente | R23: 5-Muy de acuerdo | S23: 5-Muy de acuerdo | T23: 5-Muy de acuerdo | U23: Sin respuesta | V23: 1-Nada de acuerdo | W23: 5-Muy de acuerdo | X23: 5-Muy de acuerdo | Y23: 5-Muy de acuerdo | Z23: 5-Muy de acuerdo | AA23: 5-Muy de acuerdo | AB23: 5-Muy de acuerdo | AC23: 5-Muy de acuerdo | AD23: estan muy bien pensados los trabajos finales integradores y alguna actividad intermedia siempre ayuda | AE23: 1-Sí | AF23: 5-Muy de acuerdo | AG23: 5-Muy de acuerdo | AH23: 5-Muy de acuerdo | AI23: 5-Muy de acuerdo | AJ23: 5-Muy de acuerdo | AK23: muy de acuerdo | AL23: 5-Muy de acuerdo | AM23: 5-Muy de acuerdo | AN23: 5-Muy de acuerdo | AO23: 5-Muy de acuerdo | AP23: no | AQ23: 4 | AR23: 5-Muy de acuerdo | AS23: la verdad que todo el contenido me pareció importante | AT23: es la posibilidad de conocer caminos dentro de la sociologia | AU23: creo que nada | AV23: 2-No | AW23: No corresponde | AX23: No corresponde
A24: 2025 | B24: 2do cuatrimestre | C24: 31011 | D24: Escuela Interdisciplinaria de Altos Estudios Sociales | E24: MA-GN00209 | F24: Laboratorio de Datos: webscraping y procesamiento de lenguaje natural | G24: 82009 | H24: Laboratorio de Datos tn Rosati | I24: ROSATI GERMAN FEDERICO (6114) | J24: Licenciatura en Trabajo Social | K24: 4-La materia no se dictó | L24: No corresponde | M24: No corresponde | N24: No corresponde | O24: No corresponde | P24: No corresponde | Q24: No corresponde | R24: No corresponde | S24: No corresponde | T24: No corresponde | U24: No corresponde | V24: No corresponde | W24: No corresponde | X24: No corresponde | Y24: No corresponde | Z24: No corresponde | AA24: No corresponde | AB24: No corresponde | AC24: No corresponde | AD24: No corresponde | AE24: No corresponde | AF24: No corresponde | AG24: No corresponde | AH24: No corresponde | AI24: No corresponde | AJ24: No corresponde | AK24: No corresponde | AL24: No corresponde | AM24: No corresponde | AN24: No corresponde | AO24: No corresponde | AP24: No corresponde | AQ24: No corresponde | AR24: No corresponde | AS24: No corresponde | AT24: No corresponde | AU24: No corresponde | AV24: No corresponde | AW24: No corresponde | AX24: No corresponde
A25: 2025 | B25: 2do cuatrimestre | C25: 31012 | D25: Escuela Interdisciplinaria de Altos Estudios Sociales | E25: MA-GN00209 | F25: Laboratorio de Datos: webscraping y procesamiento de lenguaje natural | G25: 82009 | H25: Laboratorio de Datos tn Rosati | I25: ROSATI GERMAN FEDERICO (6114) | J25: Licenciatura en Sociología | K25: 1-Finalicé la cursada (hayas aprobado o no) | L25: No corresponde | M25: No corresponde | N25: No corresponde | O25: No corresponde | P25: German Rosati | Q25: Excelente | R25: 5-Muy de acuerdo | S25: 5-Muy de acuerdo | T25: 5-Muy de acuerdo | U25: Sin respuesta | V25: 5-Muy de acuerdo | W25: 5-Muy de acuerdo | X25: 5-Muy de acuerdo | Y25: 5-Muy de acuerdo | Z25: 5-Muy de acuerdo | AA25: 5-Muy de acuerdo | AB25: 5-Muy de acuerdo | AC25: 5-Muy de acuerdo | AD25: Sin respuesta | AE25: 1-Sí | AF25: 5-Muy de acuerdo | AG25: 5-Muy de acuerdo | AH25: 5-Muy de acuerdo | AI25: 5-Muy de acuerdo | AJ25: 5-Muy de acuerdo | AK25: Sin respuesta | AL25: 5-Muy de acuerdo | AM25: 5-Muy de acuerdo | AN25: 5-Muy de acuerdo | AO25: 5-Muy de acuerdo | AP25: Sin respuesta | AQ25: 5-Muy de acuerdo | AR25: 5-Muy de acuerdo | AS25: Sin respuesta | AT25: Sin respuesta | AU25: Sin respuesta | AV25: 2-No | AW25: No corresponde | AX25: No corresponde
A26: 2025 | B26: 2do cuatrimestre | C26: 31013 | D26: Escuela Interdisciplinaria de Altos Estudios Sociales | E26: MA-GN00209 | F26: Laboratorio de Datos: webscraping y procesamiento de lenguaje natural | G26: 82009 | H26: Laboratorio de Datos tn Rosati | I26: ROSATI GERMAN FEDERICO (6114) | J26: Licenciatura en Sociología | K26: 1-Finalicé la cursada (hayas aprobado o no) | L26: No corresponde | M26: No corresponde | N26: No corresponde | O26: No corresponde | P26: Germán Rosatti | Q26: Excelente docente siempre puntual, cumplió con todos los puntos del programa, siempre dispuesto a explicar la cantidad de veces necesarias para que podamos entender. | R26: 5-Muy de acuerdo | S26: 5-Muy de acuerdo | T26: 5-Muy de acuerdo | U26: Sin respuesta | V26: 1-Nada de acuerdo | W26: 5-Muy de acuerdo | X26: 5-Muy de acuerdo | Y26: 5-Muy de acuerdo | Z26: 5-Muy de acuerdo | AA26: 5-Muy de acuerdo | AB26: 5-Muy de acuerdo | AC26: 5-Muy de acuerdo | AD26: el trabajo en grupo, y sostener el mismo grupo a lo largo de todo los modulos | AE26: 1-Sí | AF26: 5-Muy de acuerdo | AG26: 5-Muy de acuerdo | AH26: 5-Muy de acuerdo | AI26: 5-Muy de acuerdo | AJ26: 5-Muy de acuerdo | AK26: Sin respuesta | AL26: 5-Muy de acuerdo | AM26: 5-Muy de acuerdo | AN26: 5-Muy de acuerdo | AO26: 5-Muy de acuerdo | AP26: Sin respuesta | AQ26: 4 | AR26: 5-Muy de acuerdo | AS26: nos brinda herramientas super actualizadas para intentar entender el funcionamiento de la inteligencia artificial, y el procesamiento de datos . | AT26: está muy enfocada al procesamiento de datos y las metodologías cuantitativas, algo que se ve muy poco en la carrera. Se vuelve fundamental para quienes quieran profundizar en ese campo | AU26: Sin respuesta | AV26: 2-No | AW26: No corresponde | AX26: No corresponde
A27: 2025 | B27: 2do cuatrimestre | C27: 31014 | D27: Escuela Interdisciplinaria de Altos Estudios Sociales | E27: MA-GN00209 | F27: Laboratorio de Datos: webscraping y procesamiento de lenguaje natural | G27: 82009 | H27: Laboratorio de Datos tn Rosati | I27: ROSATI GERMAN FEDERICO (6114) | J27: Licenciatura en Sociología | K27: 1-Finalicé la cursada (hayas aprobado o no) | L27: No corresponde | M27: No corresponde | N27: No corresponde | O27: No corresponde | P27: German Rosati | Q27: de 10 | R27: 5-Muy de acuerdo | S27: 5-Muy de acuerdo | T27: 5-Muy de acuerdo | U27: Sin respuesta | V27: 1-Nada de acuerdo | W27: 5-Muy de acuerdo | X27: 5-Muy de acuerdo | Y27: 5-Muy de acuerdo | Z27: 5-Muy de acuerdo | AA27: 5-Muy de acuerdo | AB27: 5-Muy de acuerdo | AC27: 5-Muy de acuerdo | AD27: Sin respuesta | AE27: 1-Sí | AF27: 5-Muy de acuerdo | AG27: 5-Muy de acuerdo | AH27: 5-Muy de acuerdo | AI27: 5-Muy de acuerdo | AJ27: 5-Muy de acuerdo | AK27: Sin respuesta | AL27: 5-Muy de acuerdo | AM27: 5-Muy de acuerdo | AN27: 5-Muy de acuerdo | AO27: 5-Muy de acuerdo | AP27: Sin respuesta | AQ27: 5-Muy de acuerdo | AR27: 5-Muy de acuerdo | AS27: Sin respuesta | AT27: Sin respuesta | AU27: Sin respuesta | AV27: 2-No | AW27: No corresponde | AX27: No corresponde
A28: 2025 | B28: 2do cuatrimestre | C28: 31015 | D28: Escuela Interdisciplinaria de Altos Estudios Sociales | E28: MA-GN00209 | F28: Laboratorio de Datos: webscraping y procesamiento de lenguaje natural | G28: 82009 | H28: Laboratorio de Datos tn Rosati | I28: ROSATI GERMAN FEDERICO (6114) | J28: Licenciatura en Sociología | K28: 1-Finalicé la cursada (hayas aprobado o no) | L28: No corresponde | M28: No corresponde | N28: No corresponde | O28: No corresponde | P28: German Rosati | Q28: Muy buen docente. Muy comprometido con la educación | R28: 5-Muy de acuerdo | S28: 5-Muy de acuerdo | T28: 5-Muy de acuerdo | U28: Sin respuesta | V28: 5-Muy de acuerdo | W28: 5-Muy de acuerdo | X28: 5-Muy de acuerdo | Y28: 5-Muy de acuerdo | Z28: 5-Muy de acuerdo | AA28: 5-Muy de acuerdo | AB28: 5-Muy de acuerdo | AC28: 5-Muy de acuerdo | AD28: Todas | AE28: 1-Sí | AF28: 5-Muy de acuerdo | AG28: 5-Muy de acuerdo | AH28: 5-Muy de acuerdo | AI28: 5-Muy de acuerdo | AJ28: 5-Muy de acuerdo | AK28: Todo muy bien | AL28: 5-Muy de acuerdo | AM28: 5-Muy de acuerdo | AN28: 5-Muy de acuerdo | AO28: 5-Muy de acuerdo | AP28: Todo muy bien | AQ28: 5-Muy de acuerdo | AR28: 5-Muy de acuerdo | AS28: Sin respuesta | AT28: Sin respuesta | AU28: Sin respuesta | AV28: 2-No | AW28: No corresponde | AX28: No corresponde
A29: 2025 | B29: 2do cuatrimestre | C29: 31016 | D29: Escuela Interdisciplinaria de Altos Estudios Sociales | E29: MA-GN00209 | F29: Laboratorio de Datos: webscraping y procesamiento de lenguaje natural | G29: 82009 | H29: Laboratorio de Datos tn Rosati | I29: ROSATI GERMAN FEDERICO (6114) | J29: Licenciatura en Antropología Social y Cultural | K29: 1-Finalicé la cursada (hayas aprobado o no) | L29: No corresponde | M29: No corresponde | N29: No corresponde | O29: No corresponde | P29: Germán Rosati | Q29: Excelente | R29: 5-Muy de acuerdo | S29: 5-Muy de acuerdo | T29: 5-Muy de acuerdo | U29: Sin respuesta | V29: 1-Nada de acuerdo | W29: 5-Muy de acuerdo | X29: 5-Muy de acuerdo | Y29: 5-Muy de acuerdo | Z29: 5-Muy de acuerdo | AA29: 5-Muy de acuerdo | AB29: 5-Muy de acuerdo | AC29: 5-Muy de acuerdo | AD29: las presentaciones de avances por equipo | AE29: 1-Sí | AF29: 5-Muy de acuerdo | AG29: 5-Muy de acuerdo | AH29: 5-Muy de acuerdo | AI29: 5-Muy de acuerdo | AJ29: 5-Muy de acuerdo | AK29: No | AL29: 5-Muy de acuerdo | AM29: 5-Muy de acuerdo | AN29: 5-Muy de acuerdo | AO29: 5-Muy de acuerdo | AP29: No | AQ29: 5-Muy de acuerdo | AR29: 5-Muy de acuerdo | AS29: A analizar críticamente | AT29: Permite pensar las Ciencias Sociales desde perspectivas computacionales | AU29: Todo excelente sobre el docente. ***PARA LA INSTITUCIÓN: sería bueno que las computadoras del laboratorio y el proyector tuvieran mantenimiento sostenido porque es muy difícil el trabajo en el aula con computadoras que no funcionan, que se cuelgan, etc. No todxs lxs estudiantes tienen posibilidad de llevar su propia computadora al campus. Y además es una pena que teniendo un laboratorio tan lindo no pueda ser aprovechado. **** | AV29: 2-No | AW29: No corresponde | AX29: No corresponde

Sheet _BaseNum
A1: ID Encuesta | B1: Unidad Académica Nombre | C1: Materia Código | D1: Materia Nombre | E1: Comisión Código | F1: Comisión Nombre | G1: Docentes (SIU Guaraní) | H1: Carrera que estás cursando: | I1: Tu situación en relación a esta materia | J1: Docente | K1: ¿Tus comentarios sobre el/la docente? | L1: 1.1 Al inicio de la cursada el/la docente presentó y explicó claramente el programa de la materia (detalló objetivos, contenidos, cronograma, formas de trabajo y evaluación). | M1: 1.2 Hubo coherencia entre lo programado y el desarrollo de la materia. | N1: 1.3 Todos los contenidos tuvieron el tiempo suficiente para lograr los aprendizajes esperados. | O1: 1.4 El/la docente utilizó el Campus Virtual como herramienta de apoyo de la asignatura. | P1: 2.1 El/la docente relacionó conceptos con otros aprendidos con anterioridad en la misma materia o en otras materias. | Q1: 2.2 El/la docente usó ejemplos y casos relacionados con la realidad y/o el mundo laboral. | R1: 2.3 Los recursos y/o bibliografía propuestos me sirvieron para comprender las temáticas de la asignatura. | S1: 3.1 El/la docente desarrolló los temas con claridad. | T1: 3.2 El/la docente fomentó la participación en clase | U1: 3.3 Las tecnologías digitales que usó el docente me facilitaron el aprendizaje (Ejemplo: videos, recursos web, programas, presentaciones, etc.). | V1: 3.4 Las actividades propuestas en la clase contribuyeron al aprendizaje (trabajos prácticos individuales o grupales, visitas, etc.) | W1: 4 ¿Tuviste instancias de evaluación de los contenidos? | X1: 4.1 El/la docente comunicó claramente los criterios de evaluación antes de cada evaluación. | Y1: 4.2 La evaluación se correspondió con lo enseñado. | Z1: 4.3 Los instrumentos para evaluar fueron adecuados (multiple choice, examen oral, examen escrito, etc). | AA1: 4.4 Después de las evaluaciones, el/la docente realizó una devolución de los resultados a los/as estudiantes para mejorar los aprendizajes. | AB1: 4.5 El/la docente realizó las devoluciones en un tiempo adecuado. | AC1: 5.1 El/la docente estableció un ambiente agradable/seguro/de confianza para el aprendizaje. | AD1: 5.2 El/la docente promovió un trato respetuoso entre todas las personas, independientemente de su origen social, género u orientación sexual o política. | AE1: 5.3 El/la docente acogió positivamente las preguntas e inquietudes de los/as estudiantes. | AF1: 5.4 El/la docente generó interés en la materia y ganas de aprender. | AG1: 6.1 He aprendido y comprendido los contenidos de esta materia. | AH1: 6.2 La materia contribuyó a confirmar mi elección por la carrera.
A2: =IF('Base Encuesta'!#REF!="","",'Base Encuesta'!#REF!) -> #REF! | B2: =IF('Base Encuesta'!#REF!="","",'Base Encuesta'!#REF!) -> #REF! | C2: =IF('Base Encuesta'!#REF!="","",'Base Encuesta'!#REF!) -> #REF! | D2: =IF('Base Encuesta'!#REF!="","",'Base Encuesta'!#REF!) -> #REF! | E2: =IF('Base Encuesta'!#REF!="","",'Base Encuesta'!#REF!) -> #REF! | F2: =IF('Base Encuesta'!#REF!="","",'Base Encuesta'!#REF!) -> #REF! | G2: =IF('Base Encuesta'!#REF!="","",'Base Encuesta'!#REF!) -> #REF! | H2: =IF('Base Encuesta'!#REF!="","",'Base Encuesta'!#REF!) -> #REF! | I2: =IF('Base Encuesta'!#REF!="","",'Base Encuesta'!#REF!) -> #REF! | J2: =IF(OR('Base Encuesta'!#REF!="",IFERROR(VALUE(LEFT('Base Encuesta'!#REF!,1)),"")>=3),"",PROPER(TRIM('Base Encuesta'!#REF!))) -> #REF! | K2: =IF(OR('Base Encuesta'!#REF!="",IFERROR(VALUE(LEFT('Base Encuesta'!#REF!,1)),"")>=3),"",'Base Encuesta'!#REF!) -> #REF! | L2: =IF(OR('Base Encuesta'!#REF!="",IFERROR(VALUE(LEFT('Base Encuesta'!#REF!,1)),"")>=3),"",VALUE(LEFT('Base Encuesta'!#REF!,1))) -> #REF! | M2: =IF(OR('Base Encuesta'!#REF!="",IFERROR(VALUE(LEFT('Base Encuesta'!#REF!,1)),"")>=3),"",VALUE(LEFT('Base Encuesta'!#REF!,1))) -> #REF! | N2: =IF(OR('Base Encuesta'!#REF!="",IFERROR(VALUE(LEFT('Base Encuesta'!#REF!,1)),"")>=3),"",VALUE(LEFT('Base Encuesta'!#REF!,1))) -> #REF! | O2: =IF(OR('Base Encuesta'!#REF!="",IFERROR(VALUE(LEFT('Base Encuesta'!#REF!,1)),"")>=3),"",VALUE(LEFT('Base Encuesta'!#REF!,1))) -> #REF! | P2: =IF(OR('Base Encuesta'!#REF!="",IFERROR(VALUE(LEFT('Base Encuesta'!#REF!,1)),"")>=3),"",VALUE(LEFT('Base Encuesta'!#REF!,1))) -> #REF! | Q2: =IF(OR('Base Encuesta'!#REF!="",IFERROR(VALUE(LEFT('Base Encuesta'!#REF!,1)),"")>=3),"",VALUE(LEFT('Base Encuesta'!#REF!,1))) -> #REF! | R2: =IF(OR('Base Encuesta'!#REF!="",IFERROR(VALUE(LEFT('Base Encuesta'!#REF!,1)),"")>=3),"",VALUE(LEFT('Base Encuesta'!#REF!,1))) -> #REF! | S2: =IF(OR('Base Encuesta'!#REF!="",IFERROR(VALUE(LEFT('Base Encuesta'!#REF!,1)),"")>=3),"",VALUE(LEFT('Base Encuesta'!#REF!,1))) -> #REF! | ... W2: =IF(OR('Base Encuesta'!#REF!="",IFERROR(VALUE(LEFT('Base Encuesta'!#REF!,1)),"")>=3),"",VALUE(LEFT('Base Encuesta'!#REF!,1))) -> #REF! | X2: =IF(OR('Base Encuesta'!#REF!="",IFERROR(VALUE(LEFT('Base Encuesta'!#REF!,1)),"")>=3),"",IF(W2=1,VALUE(LEFT('Base Encuesta'!#REF!,1)),"")) -> #REF! | Y2: =IF(OR('Base Encuesta'!#REF!="",IFERROR(VALUE(LEFT('Base Encuesta'!#REF!,1)),"")>=3),"",IF(W2=1,VALUE(LEFT('Base Encuesta'!#REF!,1)),"")) -> #REF! | Z2: =IF(OR('Base Encuesta'!#REF!="",IFERROR(VALUE(LEFT('Base Encuesta'!#REF!,1)),"")>=3),"",IF(W2=1,VALUE(LEFT('Base Encuesta'!#REF!,1)),"")) -> #REF! | AA2: =IF(OR('Base Encuesta'!#REF!="",IFERROR(VALUE(LEFT('Base Encuesta'!#REF!,1)),"")>=3),"",IF(W2=1,VALUE(LEFT('Base Encuesta'!#REF!,1)),"")) -> #REF! | AB2: =IF(OR('Base Encuesta'!#REF!="",IFERROR(VALUE(LEFT('Base Encuesta'!#REF!,1)),"")>=3),"",IF(W2=1,VALUE(LEFT('Base Encuesta'!#REF!,1)),"")) -> #REF! | AC2: =IF(OR('Base Encuesta'!#REF!="",IFERROR(VALUE(LEFT('Base Encuesta'!#REF!,1)),"")>=3),"",VALUE(LEFT('Base Encuesta'!#REF!,1))) -> #REF! | AD2: =IF(OR('Base Encuesta'!#REF!="",IFERROR(VALUE(LEFT('Base Encuesta'!#REF!,1)),"")>=3),"",VALUE(LEFT('Base Encuesta'!#REF!,1))) -> #REF! | AE2: =IF(OR('Base Encuesta'!#REF!="",IFERROR(VALUE(LEFT('Base Encuesta'!#REF!,1)),"")>=3),"",VALUE(LEFT('Base Encuesta'!#REF!,1))) -> #REF! | AF2: =IF(OR('Base Encuesta'!#REF!="",IFERROR(VALUE(LEFT('Base Encuesta'!#REF!,1)),"")>=3),"",VALUE(LEFT('Base Encuesta'!#REF!,1))) -> #REF! | AG2: =IF(OR('Base Encuesta'!#REF!="",IFERROR(VALUE(LEFT('Base Encuesta'!#REF!,1)),"")>=3),"",VALUE(LEFT('Base Encuesta'!#REF!,1))) -> #REF! | AH2: =IF(OR('Base Encuesta'!#REF!="",IFERROR(VALUE(LEFT('Base Encuesta'!#REF!,1)),"")>=3),"",VALUE(LEFT('Base Encuesta'!#REF!,1))) -> #REF!
A3: =IF('Base Encuesta'!#REF!="","",'Base Encuesta'!#REF!) -> #REF! | B3: =IF('Base Encuesta'!#REF!="","",'Base Encuesta'!#REF!) -> #REF! | C3: =IF('Base Encuesta'!#REF!="","",'Base Encuesta'!#REF!) -> #REF! | D3: =IF('Base Encuesta'!#REF!="","",'Base Encuesta'!#REF!) -> #REF! | E3: =IF('Base Encuesta'!#REF!="","",'Base Encuesta'!#REF!) -> #REF! | F3: =IF('Base Encuesta'!#REF!="","",'Base Encuesta'!#REF!) -> #REF! | G3: =IF('Base Encuesta'!#REF!="","",'Base Encuesta'!#REF!) -> #REF! | H3: =IF('Base Encuesta'!#REF!="","",'Base Encuesta'!#REF!) -> #REF! | I3: =IF('Base Encuesta'!#REF!="","",'Base Encuesta'!#REF!) -> #REF! | J3: =IF(OR('Base Encuesta'!#REF!="",IFERROR(VALUE(LEFT('Base Encuesta'!#REF!,1)),"")>=3),"",PROPER(TRIM('Base Encuesta'!#REF!))) -> #REF! | K3: =IF(OR('Base Encuesta'!#REF!="",IFERROR(VALUE(LEFT('Base Encuesta'!#REF!,1)),"")>=3),"",'Base Encuesta'!#REF!) -> #REF! | L3: =IF(OR('Base Encuesta'!#REF!="",IFERROR(VALUE(LEFT('Base Encuesta'!#REF!,1)),"")>=3),"",VALUE(LEFT('Base Encuesta'!#REF!,1))) -> #REF! | M3: =IF(OR('Base Encuesta'!#REF!="",IFERROR(VALUE(LEFT('Base Encuesta'!#REF!,1)),"")>=3),"",VALUE(LEFT('Base Encuesta'!#REF!,1))) -> #REF! | N3: =IF(OR('Base Encuesta'!#REF!="",IFERROR(VALUE(LEFT('Base Encuesta'!#REF!,1)),"")>=3),"",VALUE(LEFT('Base Encuesta'!#REF!,1))) -> #REF! | O3: =IF(OR('Base Encuesta'!#REF!="",IFERROR(VALUE(LEFT('Base Encuesta'!#REF!,1)),"")>=3),"",VALUE(LEFT('Base Encuesta'!#REF!,1))) -> #REF! | P3: =IF(OR('Base Encuesta'!#REF!="",IFERROR(VALUE(LEFT('Base Encuesta'!#REF!,1)),"")>=3),"",VALUE(LEFT('Base Encuesta'!#REF!,1))) -> #REF! | Q3: =IF(OR('Base Encuesta'!#REF!="",IFERROR(VALUE(LEFT('Base Encuesta'!#REF!,1)),"")>=3),"",VALUE(LEFT('Base Encuesta'!#REF!,1))) -> #REF! | R3: =IF(OR('Base Encuesta'!#REF!="",IFERROR(VALUE(LEFT('Base Encuesta'!#REF!,1)),"")>=3),"",VALUE(LEFT('Base Encuesta'!#REF!,1))) -> #REF! | S3: =IF(OR('Base Encuesta'!#REF!="",IFERROR(VALUE(LEFT('Base Encuesta'!#REF!,1)),"")>=3),"",VALUE(LEFT('Base Encuesta'!#REF!,1))) -> #REF! | ... W3: =IF(OR('Base Encuesta'!#REF!="",IFERROR(VALUE(LEFT('Base Encuesta'!#REF!,1)),"")>=3),"",VALUE(LEFT('Base Encuesta'!#REF!,1))) -> #REF! | X3: =IF(OR('Base Encuesta'!#REF!="",IFERROR(VALUE(LEFT('Base Encuesta'!#REF!,1)),"")>=3),"",IF(W3=1,VALUE(LEFT('Base Encuesta'!#REF!,1)),"")) -> #REF! | Y3: =IF(OR('Base Encuesta'!#REF!="",IFERROR(VALUE(LEFT('Base Encuesta'!#REF!,1)),"")>=3),"",IF(W3=1,VALUE(LEFT('Base Encuesta'!#REF!,1)),"")) -> #REF! | Z3: =IF(OR('Base Encuesta'!#REF!="",IFERROR(VALUE(LEFT('Base Encuesta'!#REF!,1)),"")>=3),"",IF(W3=1,VALUE(LEFT('Base Encuesta'!#REF!,1)),"")) -> #REF! | AA3: =IF(OR('Base Encuesta'!#REF!="",IFERROR(VALUE(LEFT('Base Encuesta'!#REF!,1)),"")>=3),"",IF(W3=1,VALUE(LEFT('Base Encuesta'!#REF!,1)),"")) -> #REF! | AB3: =IF(OR('Base Encuesta'!#REF!="",IFERROR(VALUE(LEFT('Base Encuesta'!#REF!,1)),"")>=3),"",IF(W3=1,VALUE(LEFT('Base Encuesta'!#REF!,1)),"")) -> #REF! | AC3: =IF(OR('Base Encuesta'!#REF!="",IFERROR(VALUE(LEFT('Base Encuesta'!#REF!,1)),"")>=3),"",VALUE(LEFT('Base Encuesta'!#REF!,1))) -> #REF! | AD3: =IF(OR('Base Encuesta'!#REF!="",IFERROR(VALUE(LEFT('Base Encuesta'!#REF!,1)),"")>=3),"",VALUE(LEFT('Base Encuesta'!#REF!,1))) -> #REF! | AE3: =IF(OR('Base Encuesta'!#REF!="",IFERROR(VALUE(LEFT('Base Encuesta'!#REF!,1)),"")>=3),"",VALUE(LEFT('Base Encuesta'!#REF!,1))) -> #REF! | AF3: =IF(OR('Base Encuesta'!#REF!="",IFERROR(VALUE(LEFT('Base Encuesta'!#REF!,1)),"")>=3),"",VALUE(LEFT('Base Encuesta'!#REF!,1))) -> #REF! | AG3: =IF(OR('Base Encuesta'!#REF!="",IFERROR(VALUE(LEFT('Base Encuesta'!#REF!,1)),"")>=3),"",VALUE(LEFT('Base Encuesta'!#REF!,1))) -> #REF! | AH3: =IF(OR('Base Encuesta'!#REF!="",IFERROR(VALUE(LEFT('Base Encuesta'!#REF!,1)),"")>=3),"",VALUE(LEFT('Base Encuesta'!#REF!,1))) -> #REF!
A4: =IF('Base Encuesta'!#REF!="","",'Base Encuesta'!#REF!) -> #REF! | B4: =IF('Base Encuesta'!#REF!="","",'Base Encuesta'!#REF!) -> #REF! | C4: =IF('Base Encuesta'!#REF!="","",'Base Encuesta'!#REF!) -> #REF! | D4: =IF('Base Encuesta'!#REF!="","",'Base Encuesta'!#REF!) -> #REF! | E4: =IF('Base Encuesta'!#REF!="","",'Base Encuesta'!#REF!) -> #REF! | F4: =IF('Base Encuesta'!#REF!="","",'Base Encuesta'!#REF!) -> #REF! | G4: =IF('Base Encuesta'!#REF!="","",'Base Encuesta'!#REF!) -> #REF! | H4: =IF('Base Encuesta'!#REF!="","",'Base Encuesta'!#REF!) -> #REF! | I4: =IF('Base Encuesta'!#REF!="","",'Base Encuesta'!#REF!) -> #REF! | J4: =IF(OR('Base Encuesta'!#REF!="",IFERROR(VALUE(LEFT('Base Encuesta'!#REF!,1)),"")>=3),"",PROPER(TRIM('Base Encuesta'!#REF!))) -> #REF! | K4: =IF(OR('Base Encuesta'!#REF!="",IFERROR(VALUE(LEFT('Base Encuesta'!#REF!,1)),"")>=3),"",'Base Encuesta'!#REF!) -> #REF! | L4: =IF(OR('Base Encuesta'!#REF!="",IFERROR(VALUE(LEFT('Base Encuesta'!#REF!,1)),"")>=3),"",VALUE(LEFT('Base Encuesta'!#REF!,1))) -> #REF! | M4: =IF(OR('Base Encuesta'!#REF!="",IFERROR(VALUE(LEFT('Base Encuesta'!#REF!,1)),"")>=3),"",VALUE(LEFT('Base Encuesta'!#REF!,1))) -> #REF! | N4: =IF(OR('Base Encuesta'!#REF!="",IFERROR(VALUE(LEFT('Base Encuesta'!#REF!,1)),"")>=3),"",VALUE(LEFT('Base Encuesta'!#REF!,1))) -> #REF! | O4: =IF(OR('Base Encuesta'!#REF!="",IFERROR(VALUE(LEFT('Base Encuesta'!#REF!,1)),"")>=3),"",VALUE(LEFT('Base Encuesta'!#REF!,1))) -> #REF! | P4: =IF(OR('Base Encuesta'!#REF!="",IFERROR(VALUE(LEFT('Base Encuesta'!#REF!,1)),"")>=3),"",VALUE(LEFT('Base Encuesta'!#REF!,1))) -> #REF! | Q4: =IF(OR('Base Encuesta'!#REF!="",IFERROR(VALUE(LEFT('Base Encuesta'!#REF!,1)),"")>=3),"",VALUE(LEFT('Base Encuesta'!#REF!,1))) -> #REF! | R4: =IF(OR('Base Encuesta'!#REF!="",IFERROR(VALUE(LEFT('Base Encuesta'!#REF!,1)),"")>=3),"",VALUE(LEFT('Base Encuesta'!#REF!,1))) -> #REF! | S4: =IF(OR('Base Encuesta'!#REF!="",IFERROR(VALUE(LEFT('Base Encuesta'!#REF!,1)),"")>=3),"",VALUE(LEFT('Base Encuesta'!#REF!,1))) -> #REF! | ... W4: =IF(OR('Base Encuesta'!#REF!="",IFERROR(VALUE(LEFT('Base Encuesta'!#REF!,1)),"")>=3),"",VALUE(LEFT('Base Encuesta'!#REF!,1))) -> #REF! | X4: =IF(OR('Base Encuesta'!#REF!="",IFERROR(VALUE(LEFT('Base Encuesta'!#REF!,1)),"")>=3),"",IF(W4=1,VALUE(LEFT('Base Encuesta'!#REF!,1)),"")) -> #REF! | Y4: =IF(OR('Base Encuesta'!#REF!="",IFERROR(VALUE(LEFT('Base Encuesta'!#REF!,1)),"")>=3),"",IF(W4=1,VALUE(LEFT('Base Encuesta'!#REF!,1)),"")) -> #REF! | Z4: =IF(OR('Base Encuesta'!#REF!="",IFERROR(VALUE(LEFT('Base Encuesta'!#REF!,1)),"")>=3),"",IF(W4=1,VALUE(LEFT('Base Encuesta'!#REF!,1)),"")) -> #REF! | AA4: =IF(OR('Base Encuesta'!#REF!="",IFERROR(VALUE(LEFT('Base Encuesta'!#REF!,1)),"")>=3),"",IF(W4=1,VALUE(LEFT('Base Encuesta'!#REF!,1)),"")) -> #REF! | AB4: =IF(OR('Base Encuesta'!#REF!="",IFERROR(VALUE(LEFT('Base Encuesta'!#REF!,1)),"")>=3),"",IF(W4=1,VALUE(LEFT('Base Encuesta'!#REF!,1)),"")) -> #REF! | AC4: =IF(OR('Base Encuesta'!#REF!="",IFERROR(VALUE(LEFT('Base Encuesta'!#REF!,1)),"")>=3),"",VALUE(LEFT('Base Encuesta'!#REF!,1))) -> #REF! | AD4: =IF(OR('Base Encuesta'!#REF!="",IFERROR(VALUE(LEFT('Base Encuesta'!#REF!,1)),"")>=3),"",VALUE(LEFT('Base Encuesta'!#REF!,1))) -> #REF! | AE4: =IF(OR('Base Encuesta'!#REF!="",IFERROR(VALUE(LEFT('Base Encuesta'!#REF!,1)),"")>=3),"",VALUE(LEFT('Base Encuesta'!#REF!,1))) -> #REF! | AF4: =IF(OR('Base Encuesta'!#REF!="",IFERROR(VALUE(LEFT('Base Encuesta'!#REF!,1)),"")>=3),"",VALUE(LEFT('Base Encuesta'!#REF!,1))) -> #REF! | AG4: =IF(OR('Base Encuesta'!#REF!="",IFERROR(VALUE(LEFT('Base Encuesta'!#REF!,1)),"")>=3),"",VALUE(LEFT('Base Encuesta'!#REF!,1))) -> #REF! | AH4: =IF(OR('Base Encuesta'!#REF!="",IFERROR(VALUE(LEFT('Base Encuesta'!#REF!,1)),"")>=3),"",VALUE(LEFT('Base Encuesta'!#REF!,1))) -> #REF!
A5: =IF('Base Encuesta'!#REF!="","",'Base Encuesta'!#REF!) -> #REF! | B5: =IF('Base Encuesta'!#REF!="","",'Base Encuesta'!#REF!) -> #REF! | C5: =IF('Base Encuesta'!#REF!="","",'Base Encuesta'!#REF!) -> #REF! | D5: =IF('Base Encuesta'!#REF!="","",'Base Encuesta'!#REF!) -> #REF! | E5: =IF('Base Encuesta'!#REF!="","",'Base Encuesta'!#REF!) -> #REF! | F5: =IF('Base Encuesta'!#REF!="","",'Base Encuesta'!#REF!) -> #REF! | G5: =IF('Base Encuesta'!#REF!="","",'Base Encuesta'!#REF!) -> #REF! | H5: =IF('Base Encuesta'!#REF!="","",'Base Encuesta'!#REF!) -> #REF! | I5: =IF('Base Encuesta'!#REF!="","",'Base Encuesta'!#REF!) -> #REF! | J5: =IF(OR('Base Encuesta'!#REF!="",IFERROR(VALUE(LEFT('Base Encuesta'!#REF!,1)),"")>=3),"",PROPER(TRIM('Base Encuesta'!#REF!))) -> #REF! | K5: =IF(OR('Base Encuesta'!#REF!="",IFERROR(VALUE(LEFT('Base Encuesta'!#REF!,1)),"")>=3),"",'Base Encuesta'!#REF!) -> #REF! | L5: =IF(OR('Base Encuesta'!#REF!="",IFERROR(VALUE(LEFT('Base Encuesta'!#REF!,1)),"")>=3),"",VALUE(LEFT('Base Encuesta'!#REF!,1))) -> #REF! | M5: =IF(OR('Base Encuesta'!#REF!="",IFERROR(VALUE(LEFT('Base Encuesta'!#REF!,1)),"")>=3),"",VALUE(LEFT('Base Encuesta'!#REF!,1))) -> #REF! | N5: =IF(OR('Base Encuesta'!#REF!="",IFERROR(VALUE(LEFT('Base Encuesta'!#REF!,1)),"")>=3),"",VALUE(LEFT('Base Encuesta'!#REF!,1))) -> #REF! | O5: =IF(OR('Base Encuesta'!#REF!="",IFERROR(VALUE(LEFT('Base Encuesta'!#REF!,1)),"")>=3),"",VALUE(LEFT('Base Encuesta'!#REF!,1))) -> #REF! | P5: =IF(OR('Base Encuesta'!#REF!="",IFERROR(VALUE(LEFT('Base Encuesta'!#REF!,1)),"")>=3),"",VALUE(LEFT('Base Encuesta'!#REF!,1))) -> #REF! | Q5: =IF(OR('Base Encuesta'!#REF!="",IFERROR(VALUE(LEFT('Base Encuesta'!#REF!,1)),"")>=3),"",VALUE(LEFT('Base Encuesta'!#REF!,1))) -> #REF! | R5: =IF(OR('Base Encuesta'!#REF!="",IFERROR(VALUE(LEFT('Base Encuesta'!#REF!,1)),"")>=3),"",VALUE(LEFT('Base Encuesta'!#REF!,1))) -> #REF! | S5: =IF(OR('Base Encuesta'!#REF!="",IFERROR(VALUE(LEFT('Base Encuesta'!#REF!,1)),"")>=3),"",VALUE(LEFT('Base Encuesta'!#REF!,1))) -> #REF! | ... W5: =IF(OR('Base Encuesta'!#REF!="",IFERROR(VALUE(LEFT('Base Encuesta'!#REF!,1)),"")>=3),"",VALUE(LEFT('Base Encuesta'!#REF!,1))) -> #REF! | X5: =IF(OR('Base Encuesta'!#REF!="",IFERROR(VALUE(LEFT('Base Encuesta'!#REF!,1)),"")>=3),"",IF(W5=1,VALUE(LEFT('Base Encuesta'!#REF!,1)),"")) -> #REF! | Y5: =IF(OR('Base Encuesta'!#REF!="",IFERROR(VALUE(LEFT('Base Encuesta'!#REF!,1)),"")>=3),"",IF(W5=1,VALUE(LEFT('Base Encuesta'!#REF!,1)),"")) -> #REF! | Z5: =IF(OR('Base Encuesta'!#REF!="",IFERROR(VALUE(LEFT('Base Encuesta'!#REF!,1)),"")>=3),"",IF(W5=1,VALUE(LEFT('Base Encuesta'!#REF!,1)),"")) -> #REF! | AA5: =IF(OR('Base Encuesta'!#REF!="",IFERROR(VALUE(LEFT('Base Encuesta'!#REF!,1)),"")>=3),"",IF(W5=1,VALUE(LEFT('Base Encuesta'!#REF!,1)),"")) -> #REF! | AB5: =IF(OR('Base Encuesta'!#REF!="",IFERROR(VALUE(LEFT('Base Encuesta'!#REF!,1)),"")>=3),"",IF(W5=1,VALUE(LEFT('Base Encuesta'!#REF!,1)),"")) -> #REF! | AC5: =IF(OR('Base Encuesta'!#REF!="",IFERROR(VALUE(LEFT('Base Encuesta'!#REF!,1)),"")>=3),"",VALUE(LEFT('Base Encuesta'!#REF!,1))) -> #REF! | AD5: =IF(OR('Base Encuesta'!#REF!="",IFERROR(VALUE(LEFT('Base Encuesta'!#REF!,1)),"")>=3),"",VALUE(LEFT('Base Encuesta'!#REF!,1))) -> #REF! | AE5: =IF(OR('Base Encuesta'!#REF!="",IFERROR(VALUE(LEFT('Base Encuesta'!#REF!,1)),"")>=3),"",VALUE(LEFT('Base Encuesta'!#REF!,1))) -> #REF! | AF5: =IF(OR('Base Encuesta'!#REF!="",IFERROR(VALUE(LEFT('Base Encuesta'!#REF!,1)),"")>=3),"",VALUE(LEFT('Base Encuesta'!#REF!,1))) -> #REF! | AG5: =IF(OR('Base Encuesta'!#REF!="",IFERROR(VALUE(LEFT('Base Encuesta'!#REF!,1)),"")>=3),"",VALUE(LEFT('Base Encuesta'!#REF!,1))) -> #REF! | AH5: =IF(OR('Base Encuesta'!#REF!="",IFERROR(VALUE(LEFT('Base Encuesta'!#REF!,1)),"")>=3),"",VALUE(LEFT('Base Encuesta'!#REF!,1))) -> #REF!
A6: =IF('Base Encuesta'!#REF!="","",'Base Encuesta'!#REF!) -> #REF! | B6: =IF('Base Encuesta'!#REF!="","",'Base Encuesta'!#REF!) -> #REF! | C6: =IF('Base Encuesta'!#REF!="","",'Base Encuesta'!#REF!) -> #REF! | D6: =IF('Base Encuesta'!#REF!="","",'Base Encuesta'!#REF!) -> #REF! | E6: =IF('Base Encuesta'!#REF!="","",'Base Encuesta'!#REF!) -> #REF! | F6: =IF('Base Encuesta'!#REF!="","",'Base Encuesta'!#REF!) -> #REF! | G6: =IF('Base Encuesta'!#REF!="","",'Base Encuesta'!#REF!) -> #REF! | H6: =IF('Base Encuesta'!#REF!="","",'Base Encuesta'!#REF!) -> #REF! | I6: =IF('Base Encuesta'!#REF!="","",'Base Encuesta'!#REF!) -> #REF! | J6: =IF(OR('Base Encuesta'!#REF!="",IFERROR(VALUE(LEFT('Base Encuesta'!#REF!,1)),"")>=3),"",PROPER(TRIM('Base Encuesta'!#REF!))) -> #REF! | K6: =IF(OR('Base Encuesta'!#REF!="",IFERROR(VALUE(LEFT('Base Encuesta'!#REF!,1)),"")>=3),"",'Base Encuesta'!#REF!) -> #REF! | L6: =IF(OR('Base Encuesta'!#REF!="",IFERROR(VALUE(LEFT('Base Encuesta'!#REF!,1)),"")>=3),"",VALUE(LEFT('Base Encuesta'!#REF!,1))) -> #REF! | M6: =IF(OR('Base Encuesta'!#REF!="",IFERROR(VALUE(LEFT('Base Encuesta'!#REF!,1)),"")>=3),"",VALUE(LEFT('Base Encuesta'!#REF!,1))) -> #REF! | N6: =IF(OR('Base Encuesta'!#REF!="",IFERROR(VALUE(LEFT('Base Encuesta'!#REF!,1)),"")>=3),"",VALUE(LEFT('Base Encuesta'!#REF!,1))) -> #REF! | O6: =IF(OR('Base Encuesta'!#REF!="",IFERROR(VALUE(LEFT('Base Encuesta'!#REF!,1)),"")>=3),"",VALUE(LEFT('Base Encuesta'!#REF!,1))) -> #REF! | P6: =IF(OR('Base Encuesta'!#REF!="",IFERROR(VALUE(LEFT('Base Encuesta'!#REF!,1)),"")>=3),"",VALUE(LEFT('Base Encuesta'!#REF!,1))) -> #REF! | Q6: =IF(OR('Base Encuesta'!#REF!="",IFERROR(VALUE(LEFT('Base Encuesta'!#REF!,1)),"")>=3),"",VALUE(LEFT('Base Encuesta'!#REF!,1))) -> #REF! | R6: =IF(OR('Base Encuesta'!#REF!="",IFERROR(VALUE(LEFT('Base Encuesta'!#REF!,1)),"")>=3),"",VALUE(LEFT('Base Encuesta'!#REF!,1))) -> #REF! | S6: =IF(OR('Base Encuesta'!#REF!="",IFERROR(VALUE(LEFT('Base Encuesta'!#REF!,1)),"")>=3),"",VALUE(LEFT('Base Encuesta'!#REF!,1))) -> #REF! | ... W6: =IF(OR('Base Encuesta'!#REF!="",IFERROR(VALUE(LEFT('Base Encuesta'!#REF!,1)),"")>=3),"",VALUE(LEFT('Base Encuesta'!#REF!,1))) -> #REF! | X6: =IF(OR('Base Encuesta'!#REF!="",IFERROR(VALUE(LEFT('Base Encuesta'!#REF!,1)),"")>=3),"",IF(W6=1,VALUE(LEFT('Base Encuesta'!#REF!,1)),"")) -> #REF! | Y6: =IF(OR('Base Encuesta'!#REF!="",IFERROR(VALUE(LEFT('Base Encuesta'!#REF!,1)),"")>=3),"",IF(W6=1,VALUE(LEFT('Base Encuesta'!#REF!,1)),"")) -> #REF! | Z6: =IF(OR('Base Encuesta'!#REF!="",IFERROR(VALUE(LEFT('Base Encuesta'!#REF!,1)),"")>=3),"",IF(W6=1,VALUE(LEFT('Base Encuesta'!#REF!,1)),"")) -> #REF! | AA6: =IF(OR('Base Encuesta'!#REF!="",IFERROR(VALUE(LEFT('Base Encuesta'!#REF!,1)),"")>=3),"",IF(W6=1,VALUE(LEFT('Base Encuesta'!#REF!,1)),"")) -> #REF! | AB6: =IF(OR('Base Encuesta'!#REF!="",IFERROR(VALUE(LEFT('Base Encuesta'!#REF!,1)),"")>=3),"",IF(W6=1,VALUE(LEFT('Base Encuesta'!#REF!,1)),"")) -> #REF! | AC6: =IF(OR('Base Encuesta'!#REF!="",IFERROR(VALUE(LEFT('Base Encuesta'!#REF!,1)),"")>=3),"",VALUE(LEFT('Base Encuesta'!#REF!,1))) -> #REF! | AD6: =IF(OR('Base Encuesta'!#REF!="",IFERROR(VALUE(LEFT('Base Encuesta'!#REF!,1)),"")>=3),"",VALUE(LEFT('Base Encuesta'!#REF!,1))) -> #REF! | AE6: =IF(OR('Base Encuesta'!#REF!="",IFERROR(VALUE(LEFT('Base Encuesta'!#REF!,1)),"")>=3),"",VALUE(LEFT('Base Encuesta'!#REF!,1))) -> #REF! | AF6: =IF(OR('Base Encuesta'!#REF!="",IFERROR(VALUE(LEFT('Base Encuesta'!#REF!,1)),"")>=3),"",VALUE(LEFT('Base Encuesta'!#REF!,1))) -> #REF! | AG6: =IF(OR('Base Encuesta'!#REF!="",IFERROR(VALUE(LEFT('Base Encuesta'!#REF!,1)),"")>=3),"",VALUE(LEFT('Base Encuesta'!#REF!,1))) -> #REF! | AH6: =IF(OR('Base Encuesta'!#REF!="",IFERROR(VALUE(LEFT('Base Encuesta'!#REF!,1)),"")>=3),"",VALUE(LEFT('Base Encuesta'!#REF!,1))) -> #REF!
A7: =IF('Base Encuesta'!#REF!="","",'Base Encuesta'!#REF!) -> #REF! | B7: =IF('Base Encuesta'!#REF!="","",'Base Encuesta'!#REF!) -> #REF! | C7: =IF('Base Encuesta'!#REF!="","",'Base Encuesta'!#REF!) -> #REF! | D7: =IF('Base Encuesta'!#REF!="","",'Base Encuesta'!#REF!) -> #REF! | E7: =IF('Base Encuesta'!#REF!="","",'Base Encuesta'!#REF!) -> #REF! | F7: =IF('Base Encuesta'!#REF!="","",'Base Encuesta'!#REF!) -> #REF! | G7: =IF('Base Encuesta'!#REF!="","",'Base Encuesta'!#REF!) -> #REF! | H7: =IF('Base Encuesta'!#REF!="","",'Base Encuesta'!#REF!) -> #REF! | I7: =IF('Base Encuesta'!#REF!="","",'Base Encuesta'!#REF!) -> #REF! | J7: =IF(OR('Base Encuesta'!#REF!="",IFERROR(VALUE(LEFT('Base Encuesta'!#REF!,1)),"")>=3),"",PROPER(TRIM('Base Encuesta'!#REF!))) -> #REF! | K7: =IF(OR('Base Encuesta'!#REF!="",IFERROR(VALUE(LEFT('Base Encuesta'!#REF!,1)),"")>=3),"",'Base Encuesta'!#REF!) -> #REF! | L7: =IF(OR('Base Encuesta'!#REF!="",IFERROR(VALUE(LEFT('Base Encuesta'!#REF!,1)),"")>=3),"",VALUE(LEFT('Base Encuesta'!#REF!,1))) -> #REF! | M7: =IF(OR('Base Encuesta'!#REF!="",IFERROR(VALUE(LEFT('Base Encuesta'!#REF!,1)),"")>=3),"",VALUE(LEFT('Base Encuesta'!#REF!,1))) -> #REF! | N7: =IF(OR('Base Encuesta'!#REF!="",IFERROR(VALUE(LEFT('Base Encuesta'!#REF!,1)),"")>=3),"",VALUE(LEFT('Base Encuesta'!#REF!,1))) -> #REF! | O7: =IF(OR('Base Encuesta'!#REF!="",IFERROR(VALUE(LEFT('Base Encuesta'!#REF!,1)),"")>=3),"",VALUE(LEFT('Base Encuesta'!#REF!,1))) -> #REF! | P7: =IF(OR('Base Encuesta'!#REF!="",IFERROR(VALUE(LEFT('Base Encuesta'!#REF!,1)),"")>=3),"",VALUE(LEFT('Base Encuesta'!#REF!,1))) -> #REF! | Q7: =IF(OR('Base Encuesta'!#REF!="",IFERROR(VALUE(LEFT('Base Encuesta'!#REF!,1)),"")>=3),"",VALUE(LEFT('Base Encuesta'!#REF!,1))) -> #REF! | R7: =IF(OR('Base Encuesta'!#REF!="",IFERROR(VALUE(LEFT('Base Encuesta'!#REF!,1)),"")>=3),"",VALUE(LEFT('Base Encuesta'!#REF!,1))) -> #REF! | S7: =IF(OR('Base Encuesta'!#REF!="",IFERROR(VALUE(LEFT('Base Encuesta'!#REF!,1)),"")>=3),"",VALUE(LEFT('Base Encuesta'!#REF!,1))) -> #REF! | ... W7: =IF(OR('Base Encuesta'!#REF!="",IFERROR(VALUE(LEFT('Base Encuesta'!#REF!,1)),"")>=3),"",VALUE(LEFT('Base Encuesta'!#REF!,1))) -> #REF! | X7: =IF(OR('Base Encuesta'!#REF!="",IFERROR(VALUE(LEFT('Base Encuesta'!#REF!,1)),"")>=3),"",IF(W7=1,VALUE(LEFT('Base Encuesta'!#REF!,1)),"")) -> #REF! | Y7: =IF(OR('Base Encuesta'!#REF!="",IFERROR(VALUE(LEFT('Base Encuesta'!#REF!,1)),"")>=3),"",IF(W7=1,VALUE(LEFT('Base Encuesta'!#REF!,1)),"")) -> #REF! | Z7: =IF(OR('Base Encuesta'!#REF!="",IFERROR(VALUE(LEFT('Base Encuesta'!#REF!,1)),"")>=3),"",IF(W7=1,VALUE(LEFT('Base Encuesta'!#REF!,1)),"")) -> #REF! | AA7: =IF(OR('Base Encuesta'!#REF!="",IFERROR(VALUE(LEFT('Base Encuesta'!#REF!,1)),"")>=3),"",IF(W7=1,VALUE(LEFT('Base Encuesta'!#REF!,1)),"")) -> #REF! | AB7: =IF(OR('Base Encuesta'!#REF!="",IFERROR(VALUE(LEFT('Base Encuesta'!#REF!,1)),"")>=3),"",IF(W7=1,VALUE(LEFT('Base Encuesta'!#REF!,1)),"")) -> #REF! | AC7: =IF(OR('Base Encuesta'!#REF!="",IFERROR(VALUE(LEFT('Base Encuesta'!#REF!,1)),"")>=3),"",VALUE(LEFT('Base Encuesta'!#REF!,1))) -> #REF! | AD7: =IF(OR('Base Encuesta'!#REF!="",IFERROR(VALUE(LEFT('Base Encuesta'!#REF!,1)),"")>=3),"",VALUE(LEFT('Base Encuesta'!#REF!,1))) -> #REF! | AE7: =IF(OR('Base Encuesta'!#REF!="",IFERROR(VALUE(LEFT('Base Encuesta'!#REF!,1)),"")>=3),"",VALUE(LEFT('Base Encuesta'!#REF!,1))) -> #REF! | AF7: =IF(OR('Base Encuesta'!#REF!="",IFERROR(VALUE(LEFT('Base Encuesta'!#REF!,1)),"")>=3),"",VALUE(LEFT('Base Encuesta'!#REF!,1))) -> #REF! | AG7: =IF(OR('Base Encuesta'!#REF!="",IFERROR(VALUE(LEFT('Base Encuesta'!#REF!,1)),"")>=3),"",VALUE(LEFT('Base Encuesta'!#REF!,1))) -> #REF! | AH7: =IF(OR('Base Encuesta'!#REF!="",IFERROR(VALUE(LEFT('Base Encuesta'!#REF!,1)),"")>=3),"",VALUE(LEFT('Base Encuesta'!#REF!,1))) -> #REF!
A8: =IF('Base Encuesta'!#REF!="","",'Base Encuesta'!#REF!) -> #REF! | B8: =IF('Base Encuesta'!#REF!="","",'Base Encuesta'!#REF!) -> #REF! | C8: =IF('Base Encuesta'!#REF!="","",'Base Encuesta'!#REF!) -> #REF! | D8: =IF('Base Encuesta'!#REF!="","",'Base Encuesta'!#REF!) -> #REF! | E8: =IF('Base Encuesta'!#REF!="","",'Base Encuesta'!#REF!) -> #REF! | F8: =IF('Base Encuesta'!#REF!="","",'Base Encuesta'!#REF!) -> #REF! | G8: =IF('Base Encuesta'!#REF!="","",'Base Encuesta'!#REF!) -> #REF! | H8: =IF('Base Encuesta'!#REF!="","",'Base Encuesta'!#REF!) -> #REF! | I8: =IF('Base Encuesta'!#REF!="","",'Base Encuesta'!#REF!) -> #REF! | J8: =IF(OR('Base Encuesta'!#REF!="",IFERROR(VALUE(LEFT('Base Encuesta'!#REF!,1)),"")>=3),"",PROPER(TRIM('Base Encuesta'!#REF!))) -> #REF! | K8: =IF(OR('Base Encuesta'!#REF!="",IFERROR(VALUE(LEFT('Base Encuesta'!#REF!,1)),"")>=3),"",'Base Encuesta'!#REF!) -> #REF! | L8: =IF(OR('Base Encuesta'!#REF!="",IFERROR(VALUE(LEFT('Base Encuesta'!#REF!,1)),"")>=3),"",VALUE(LEFT('Base Encuesta'!#REF!,1))) -> #REF! | M8: =IF(OR('Base Encuesta'!#REF!="",IFERROR(VALUE(LEFT('Base Encuesta'!#REF!,1)),"")>=3),"",VALUE(LEFT('Base Encuesta'!#REF!,1))) -> #REF! | N8: =IF(OR('Base Encuesta'!#REF!="",IFERROR(VALUE(LEFT('Base Encuesta'!#REF!,1)),"")>=3),"",VALUE(LEFT('Base Encuesta'!#REF!,1))) -> #REF! | O8: =IF(OR('Base Encuesta'!#REF!="",IFERROR(VALUE(LEFT('Base Encuesta'!#REF!,1)),"")>=3),"",VALUE(LEFT('Base Encuesta'!#REF!,1))) -> #REF! | P8: =IF(OR('Base Encuesta'!#REF!="",IFERROR(VALUE(LEFT('Base Encuesta'!#REF!,1)),"")>=3),"",VALUE(LEFT('Base Encuesta'!#REF!,1))) -> #REF! | Q8: =IF(OR('Base Encuesta'!#REF!="",IFERROR(VALUE(LEFT('Base Encuesta'!#REF!,1)),"")>=3),"",VALUE(LEFT('Base Encuesta'!#REF!,1))) -> #REF! | R8: =IF(OR('Base Encuesta'!#REF!="",IFERROR(VALUE(LEFT('Base Encuesta'!#REF!,1)),"")>=3),"",VALUE(LEFT('Base Encuesta'!#REF!,1))) -> #REF! | S8: =IF(OR('Base Encuesta'!#REF!="",IFERROR(VALUE(LEFT('Base Encuesta'!#REF!,1)),"")>=3),"",VALUE(LEFT('Base Encuesta'!#REF!,1))) -> #REF! | ... W8: =IF(OR('Base Encuesta'!#REF!="",IFERROR(VALUE(LEFT('Base Encuesta'!#REF!,1)),"")>=3),"",VALUE(LEFT('Base Encuesta'!#REF!,1))) -> #REF! | X8: =IF(OR('Base Encuesta'!#REF!="",IFERROR(VALUE(LEFT('Base Encuesta'!#REF!,1)),"")>=3),"",IF(W8=1,VALUE(LEFT('Base Encuesta'!#REF!,1)),"")) -> #REF! | Y8: =IF(OR('Base Encuesta'!#REF!="",IFERROR(VALUE(LEFT('Base Encuesta'!#REF!,1)),"")>=3),"",IF(W8=1,VALUE(LEFT('Base Encuesta'!#REF!,1)),"")) -> #REF! | Z8: =IF(OR('Base Encuesta'!#REF!="",IFERROR(VALUE(LEFT('Base Encuesta'!#REF!,1)),"")>=3),"",IF(W8=1,VALUE(LEFT('Base Encuesta'!#REF!,1)),"")) -> #REF! | AA8: =IF(OR('Base Encuesta'!#REF!="",IFERROR(VALUE(LEFT('Base Encuesta'!#REF!,1)),"")>=3),"",IF(W8=1,VALUE(LEFT('Base Encuesta'!#REF!,1)),"")) -> #REF! | AB8: =IF(OR('Base Encuesta'!#REF!="",IFERROR(VALUE(LEFT('Base Encuesta'!#REF!,1)),"")>=3),"",IF(W8=1,VALUE(LEFT('Base Encuesta'!#REF!,1)),"")) -> #REF! | AC8: =IF(OR('Base Encuesta'!#REF!="",IFERROR(VALUE(LEFT('Base Encuesta'!#REF!,1)),"")>=3),"",VALUE(LEFT('Base Encuesta'!#REF!,1))) -> #REF! | AD8: =IF(OR('Base Encuesta'!#REF!="",IFERROR(VALUE(LEFT('Base Encuesta'!#REF!,1)),"")>=3),"",VALUE(LEFT('Base Encuesta'!#REF!,1))) -> #REF! | AE8: =IF(OR('Base Encuesta'!#REF!="",IFERROR(VALUE(LEFT('Base Encuesta'!#REF!,1)),"")>=3),"",VALUE(LEFT('Base Encuesta'!#REF!,1))) -> #REF! | AF8: =IF(OR('Base Encuesta'!#REF!="",IFERROR(VALUE(LEFT('Base Encuesta'!#REF!,1)),"")>=3),"",VALUE(LEFT('Base Encuesta'!#REF!,1))) -> #REF! | AG8: =IF(OR('Base Encuesta'!#REF!="",IFERROR(VALUE(LEFT('Base Encuesta'!#REF!,1)),"")>=3),"",VALUE(LEFT('Base Encuesta'!#REF!,1))) -> #REF! | AH8: =IF(OR('Base Encuesta'!#REF!="",IFERROR(VALUE(LEFT('Base Encuesta'!#REF!,1)),"")>=3),"",VALUE(LEFT('Base Encuesta'!#REF!,1))) -> #REF!
A9: =IF('Base Encuesta'!#REF!="","",'Base Encuesta'!#REF!) -> #REF! | B9: =IF('Base Encuesta'!#REF!="","",'Base Encuesta'!#REF!) -> #REF! | C9: =IF('Base Encuesta'!#REF!="","",'Base Encuesta'!#REF!) -> #REF! | D9: =IF('Base Encuesta'!#REF!="","",'Base Encuesta'!#REF!) -> #REF! | E9: =IF('Base Encuesta'!#REF!="","",'Base Encuesta'!#REF!) -> #REF! | F9: =IF('Base Encuesta'!#REF!="","",'Base Encuesta'!#REF!) -> #REF! | G9: =IF('Base Encuesta'!#REF!="","",'Base Encuesta'!#REF!) -> #REF! | H9: =IF('Base Encuesta'!#REF!="","",'Base Encuesta'!#REF!) -> #REF! | I9: =IF('Base Encuesta'!#REF!="","",'Base Encuesta'!#REF!) -> #REF! | J9: =IF(OR('Base Encuesta'!#REF!="",IFERROR(VALUE(LEFT('Base Encuesta'!#REF!,1)),"")>=3),"",PROPER(TRIM('Base Encuesta'!#REF!))) -> #REF! | K9: =IF(OR('Base Encuesta'!#REF!="",IFERROR(VALUE(LEFT('Base Encuesta'!#REF!,1)),"")>=3),"",'Base Encuesta'!#REF!) -> #REF! | L9: =IF(OR('Base Encuesta'!#REF!="",IFERROR(VALUE(LEFT('Base Encuesta'!#REF!,1)),"")>=3),"",VALUE(LEFT('Base Encuesta'!#REF!,1))) -> #REF! | M9: =IF(OR('Base Encuesta'!#REF!="",IFERROR(VALUE(LEFT('Base Encuesta'!#REF!,1)),"")>=3),"",VALUE(LEFT('Base Encuesta'!#REF!,1))) -> #REF! | N9: =IF(OR('Base Encuesta'!#REF!="",IFERROR(VALUE(LEFT('Base Encuesta'!#REF!,1)),"")>=3),"",VALUE(LEFT('Base Encuesta'!#REF!,1))) -> #REF! | O9: =IF(OR('Base Encuesta'!#REF!="",IFERROR(VALUE(LEFT('Base Encuesta'!#REF!,1)),"")>=3),"",VALUE(LEFT('Base Encuesta'!#REF!,1))) -> #REF! | P9: =IF(OR('Base Encuesta'!#REF!="",IFERROR(VALUE(LEFT('Base Encuesta'!#REF!,1)),"")>=3),"",VALUE(LEFT('Base Encuesta'!#REF!,1))) -> #REF! | Q9: =IF(OR('Base Encuesta'!#REF!="",IFERROR(VALUE(LEFT('Base Encuesta'!#REF!,1)),"")>=3),"",VALUE(LEFT('Base Encuesta'!#REF!,1))) -> #REF! | R9: =IF(OR('Base Encuesta'!#REF!="",IFERROR(VALUE(LEFT('Base Encuesta'!#REF!,1)),"")>=3),"",VALUE(LEFT('Base Encuesta'!#REF!,1))) -> #REF! | S9: =IF(OR('Base Encuesta'!#REF!="",IFERROR(VALUE(LEFT('Base Encuesta'!#REF!,1)),"")>=3),"",VALUE(LEFT('Base Encuesta'!#REF!,1))) -> #REF! | ... W9: =IF(OR('Base Encuesta'!#REF!="",IFERROR(VALUE(LEFT('Base Encuesta'!#REF!,1)),"")>=3),"",VALUE(LEFT('Base Encuesta'!#REF!,1))) -> #REF! | X9: =IF(OR('Base Encuesta'!#REF!="",IFERROR(VALUE(LEFT('Base Encuesta'!#REF!,1)),"")>=3),"",IF(W9=1,VALUE(LEFT('Base Encuesta'!#REF!,1)),"")) -> #REF! | Y9: =IF(OR('Base Encuesta'!#REF!="",IFERROR(VALUE(LEFT('Base Encuesta'!#REF!,1)),"")>=3),"",IF(W9=1,VALUE(LEFT('Base Encuesta'!#REF!,1)),"")) -> #REF! | Z9: =IF(OR('Base Encuesta'!#REF!="",IFERROR(VALUE(LEFT('Base Encuesta'!#REF!,1)),"")>=3),"",IF(W9=1,VALUE(LEFT('Base Encuesta'!#REF!,1)),"")) -> #REF! | AA9: =IF(OR('Base Encuesta'!#REF!="",IFERROR(VALUE(LEFT('Base Encuesta'!#REF!,1)),"")>=3),"",IF(W9=1,VALUE(LEFT('Base Encuesta'!#REF!,1)),"")) -> #REF! | AB9: =IF(OR('Base Encuesta'!#REF!="",IFERROR(VALUE(LEFT('Base Encuesta'!#REF!,1)),"")>=3),"",IF(W9=1,VALUE(LEFT('Base Encuesta'!#REF!,1)),"")) -> #REF! | AC9: =IF(OR('Base Encuesta'!#REF!="",IFERROR(VALUE(LEFT('Base Encuesta'!#REF!,1)),"")>=3),"",VALUE(LEFT('Base Encuesta'!#REF!,1))) -> #REF! | AD9: =IF(OR('Base Encuesta'!#REF!="",IFERROR(VALUE(LEFT('Base Encuesta'!#REF!,1)),"")>=3),"",VALUE(LEFT('Base Encuesta'!#REF!,1))) -> #REF! | AE9: =IF(OR('Base Encuesta'!#REF!="",IFERROR(VALUE(LEFT('Base Encuesta'!#REF!,1)),"")>=3),"",VALUE(LEFT('Base Encuesta'!#REF!,1))) -> #REF! | AF9: =IF(OR('Base Encuesta'!#REF!="",IFERROR(VALUE(LEFT('Base Encuesta'!#REF!,1)),"")>=3),"",VALUE(LEFT('Base Encuesta'!#REF!,1))) -> #REF! | AG9: =IF(OR('Base Encuesta'!#REF!="",IFERROR(VALUE(LEFT('Base Encuesta'!#REF!,1)),"")>=3),"",VALUE(LEFT('Base Encuesta'!#REF!,1))) -> #REF! | AH9: =IF(OR('Base Encuesta'!#REF!="",IFERROR(VALUE(LEFT('Base Encuesta'!#REF!,1)),"")>=3),"",VALUE(LEFT('Base Encuesta'!#REF!,1))) -> #REF!
